Workbook

Sheet SOCIOS
A1: NOMBRE Y APELLIDOS | B1: ol | C1: NAF | D1: NIF/NIE | E1: CC | F1: FECHA NACIMIENTO | G1: GRUPO | H1: CATEGORIA PROFESIONAL | J1: FECHA CADUCIDAD | K1: NACIONALIDAD
A2: NICOLETTA VALENTE | B2: 471018649632 | C2: 1018649632 | D2: X6105215A | E2: 186282967 | F2: 28638
A3: IGNACIO MARTIN RICCI | B3: 081279985491 | C3: 1279985491 | D3: Y2639496F | E3: 186282967 | F3: 31873 | G3: 3 | H3: 6000327 | I3: ARTISTA DE CIRCO
A4: GUILLERMO VIZCAINO LLOBERA | B4: 071045708077 | C4: 1045708077 | D4: 41522123Q | E4: 186282967 | F4: 31887
A5: JORGE ALBUERNE JUANCO | B5: 331015957038 | C5: 1015957038 | D5: 09422055J | E5: 186282967 | F5: 27351 | G5: 3 | H5: 6000327 | I5: ARTISTA DE CIRCO
A6: EMMANUEL JOEL DANET | B6: 071005945454 | C6: 1005945454 | D6: X1981863E | E6: 186282967 | F6: 26167 | G6: 3 | H6: 6000320 | I6: ACTOR TEATRO
A7: ELISABETTA CAU | B7: 081295553284 | C7: 1295553284 | D7: Y3339605L | E7: 182521791 | F7: 27883
A8: NICOLAS BENINCASA | B8: 081227131003 | C8: 1227131003 | D8: Y0082226S | E8: 186282967 | F8: 29195 | G8: 3 | H8: 6000327 | I8: ARTISTA DE CIRCO
A9: JOAQUIN LAGUARDE | B9: 081173328840 | C9: 1173328840 | D9: X3428235Q | E9: 186282967 | F9: 27313 | G9: 5 | H9: 6100512 | I9: MONTADOR
A10: FRANCISCO ROJAS DYVINETZ | B10: 471019949869 | C10: 1019949869 | D10: 26320591N | E10: 186282967 | F10: 28654
A11: RODOLFO ALFREDO SAMPEDRO | B11: 041039961584 | C11: 1039961584 | D11: X6513507E | E11: 186282967 | F11: 26196
A12: HECTOR GRANADA COROLEU | B12: 081052236161 | C12: 1052236161 | D12: 46138182K | E12: 186282967 | F12: 28781 | G12: 5 | H12: 6100519 | I12: PRIMER AYUDANTE PRODUCCION
A13: ANTONIO BLANCO HERMOSIN | B13: 081078871856 | C13: 1078871856 | D13: 43453709Q | E13: 186282967 | F13: 29540
A14: MARIA SOL VAZQUEZ NICOLOFF | B14: 081174888823 | C14: 1174888823 | D14: 49322021Q | E14: 186282967 | F14: 29673 | G14: 3 | H14: 6000325
A15: ADRIANA SEGURADO MENDEZ | B15: 081098996528 | C15: 1098996528 | D15: 47634414B | E15: 186282967 | F15: 29855 | G15: 3 | H15: 6000320 | I15: ACTOR TEATRO
A16: JUAN CARLOS SABATE | B16: 081255998607 | C16: 1255998607 | D16: Y0452587F | E16: 182521791 | F16: 29631
A17: XAVIER GARCÍA ILLA | B17: 081069372122 | C17: 1069372122 | D17: 38135612W | E17: 186282967 | F17: 29458 | G17: 3 | H17: 6000326 | I17: MÚSIC
A18: ALBERT REQUENA SERRA | B18: 080543963801 | C18: 0543963801 | D18: 40992217F | E18: 186282967 | F18: 27876 | G18: 3 | H18: 6000320 | I18: ACTOR TEATRO
A19: AINHOA ROCA VIELBA AUTONOMA | B19: 081103701129 | C19: 1103701129 | D19: 52916243M | E19: 186282967 | F19: 3 | G19: 3 | H19: 6000320 | I19: ACTOR TEATRO
A20: JADE MORIN | B20: 281316149082 | C20: 1316149082 | D20: Y0276785V | E20: 186282967 | F20: 30224 | G20: 3 | H20: 6000327 | I20: ARTISTA DE CIRCO
A21: PATXI URLEZAGA MORUGARREN | B21: 201007912318 | C21: 1007912318 | D21: 44170136Q | E21: 186282967 | F21: 28870
A22: MAURO DANIEL PAGANINI POLLINI | B22: 081180605052 | C22: 1180605052 | D22: 21755736J | E22: 186282967 | F22: 29011 | G22: 3 | H22: 6000327 | I22: ARTISTA DE CIRCO
A23: TUPAC MARTÍN DAMIA | B23: 331041402360 | C23: 1041402360 | D23: X8921944Z | E23: 182521791 | F23: 30391
A24: STINA MARIA KOPRA | B24: 081323731380 | C24: 1323731380 | D24: Y3361816N | E24: 186282967 | F24: 30747 | K24: FINLANDIA
A25: ANGEL ROSET ROSADO | B25: 081093008594 | C25: 1093008594 | D25: 39363487E | E25: 186282967 | F25: 29978 | G25: 3 | H25: 6000327 | I25: ARTISTA DE CIRCO
A26: VICTOR RUBILAR PANASIUK | B26: 081323732794 | C26: 1323732794 | D26: Y3361795Z | E26: 186282967 | F26: 29426 | G26: 3 | H26: 6000327 | I26: ARTISTA DE CIRCO
A27: DOMINIK SRZEDNICKI | B27: 481049393393 | C27: 1049393393 | D27: Y0165523Y | E27: 186282967 | F27: 28302
A28: MARTA GARCIA CARDELLACH | B28: 081158972638 | C28: 1158972638 | D28: 45882493T | E28: 186282967 | F28: 32791 | G28: 7 | H28: 6100739 | I28: 2º AYUDANTE PRODUCCION
A29: MARIA INES GUARDIA ARARIO | B29: 081163788787 | C29: 1163788787 | D29: 23820881B | E29: 186282967 | F29: 29651 | G29: 3 | H29: 6000327 | I29: ARTISTA DE CIRCO
A30: MERITXELL ESTEBAN JANOT | B30: 080422563752 | C30: 0422563752 | D30: 38509140X | E30: 186282967 | F30: 23468 | G30: 4 | H30: 6100407 | I30: ESCENOGRAFA
A31: MARC ANTOLI JUSTICIA | B31: 081238203349 | C31: 1238203349 | D31: 48088795G | E31: 186282967 | F31: 34445
A32: CLAUDIA BALCELLS CARNER | B32: 081247381569 | C32: 1247381569 | D32: 48039310S | E32: 186282967 | F32: 34224
A33: ANTONIO ALCALDE SEBASTIAN | B33: 081224816642 | C33: 1224816642 | D33: 53085023B | E33: 186282967 | F33: 33600
A34: SALVADOR RIBA MEGIAS | B34: 081093512893 | C34: 1093512893 | D34: 43443782W | E34: 186282967 | F34: 29912
A35: SONIA GOMEZ VICENTE | B35: 430059140462 | C35: 0059140462 | D35: 52603529E | E35: 186282967 | F35: 26989 | G35: 3 | H35: 6000325 | I35: BAILARINA
A36: JORDI QUEROL GIMENEZ | B36: 081094780159 | C36: 1094780159 | D36: 44416130W | E36: 186282967 | F36: 29848
A37: JOSEP MASNOU DOU | B37: 081232647875 | C37: 1232647875 | D37: 47817962L | E37: 186282967 | F37: 32819
A38: GEMMA BERENGUER BALAT | B38: 081096576881 | C38: 1096576881 | D38: 46696296V | E38: 186282967 | F38: 29308 | G38: 4 | H38: 6100406 | I38: DECORADORA
A39: ORIOL PLA SOLINA | B39: 081167337573 | C39: 1167337573 | D39: 46151270E | E39: 186282967 | F39: 34076 | G39: 3 | H39: 6000320 | I39: ACTRIZ TEATRO
A40: SONIA ESPINOSA MUÑOZ | B40: 081081707892 | C40: 1081707892 | D40: 46963416S | E40: 186282967 | F40: 28794
...

Sheet PUNTUALES
A1: CODIGO | B1: SEXO | C1: NOMBRE Y APELLIDOS | D1: NAF | E1: NAF | F1: NIF/NIE | G1: CC | H1: FECHA NACIMIENTO | I1: GRUPO | J1: CATEGORIA PROFESIONAL | L1: FECHA CADUCIDAD | M1: NACIONALIDAD
A2: 1 | B2: Mujer | C2: NATALIA GARCIA REDON | D2: 81035546404 | E2: 1035546404 | F2: 53074571R | G2: 182520478 | H2: 28189
A3: 2 | B3: Mujer | C3: MARIA MANUELA GRACIAN ALVAREZ | D3: 81140685613 | E3: 1140685613 | F3: 49551598F | G3: =G2 -> 182520478 | H3: 28291 | J3: SOCIO COOPERATIVA
A4: 5 | B4: Hombre | C4: MARC FLORENCIO VILLA | D4: 71016176631 | E4: 1016176631 | F4: 43099262E | G4: 186282967 | H4: 27090
A5: 6 | B5: Mujer | C5: ELENA XIBILLE RIERA | D5: 81112028173 | E5: 1112028173 | F5: 43102745D | G5: 186282967 | H5: 28708
A6: 7 | B6: Mujer | C6: RUGIADA GRIGNANI | D6: 81276689111 | E6: 1276689111 | F6: Y2831353K | G6: 186282967 | H6: 32322 | K6: ITA
A7: 8 | B7: Hombre | C7: TIMOTEO GRIGNANI | D7: 81276691939 | E7: 1276691939 | F7: Y2828096F | G7: 186282967 | H7: 33550 | K7: ITA
A8: 9 | B8: Mujer | C8: FABIANA JUDITH RUIZ DIAZ BELTRAN | D8: 81189866734 | E8: 1189866734 | F8: X6183816J | G8: 186282967 | H8: 29818 | J8: VAL 2020 | K8: FCURC URU
A9: 10 | B9: Hombre | C9: ALBERTO SOLANO BARRERA BITAUBE | D9: 111034429337 | E9: 1034429337 | F9: 31709603D | G9: 186282967 | H9: 28320
A10: 11 | B10: Mujer | C10: LUNA ZAPATA BLANCO | D10: 71016750042 | E10: 1016750042 | F10: 43121676B | G10: 186282967 | H10: 28769
A11: 12 | B11: Hombre | C11: CARLOS HERNAN EXPOSITO | D11: 71059675370 | E11: 1059675370 | F11: Y1329560j | G11: 186282967 | H11: 29515 | J11: VAL 15072025 | K11: RCUFC
A12: 13 | B12: Mujer | C12: LUCIA LOURDES QUIROS SAEZ | D12: 71042179907 | E12: 1042179907 | F12: X7840382G | G12: 186282967 | H12: 27313 | K12: ITA
A13: 15 | B13: Hombre | C13: CLAUDIO DANIEL DORIGO | D13: 81185847702 | E13: 1185847702 | F13: X6625246G | G13: 186282967 | H13: 28638 | K13: ITA
A14: 17 | B14: Hombre | C14: ALEJANDRO NICOLAS MUÑOZ | D14: 81197175985 | E14: 1197175985 | F14: X7070128C | G14: 186282967 | H14: 27290 | K14: ITA
A15: 18 | B15: Mujer | C15: RUTH DELGADO OCHOA | D15: 81117119966 | E15: 1117119966 | F15: 52596070S | G15: 186282967 | H15: 32604
A16: 20 | B16: Mujer | C16: INGRID ESPERANZA BERMAN MARIN | D16: 81187766480 | E16: 1187766480 | F16: 24557861W | G16: 186282967 | H16: 30943 | J16: (NO HAY NIE ESCANEADO EN SU CARPETA)
A17: 21 | B17: Hombre | C17: QUIM GIRON FIGUEROLA | D17: 81138084191 | E17: 1138084191 | F17: 43633759E | G17: 186282967 | H17: 31083
A18: 22 | B18: Hombre | C18: ANDREU BASEIRIA VIRGILI | D18: 80504123978 | E18: 0504123978 | F18: 36981271P | G18: 186282967 | H18: 24541
A19: 23 | B19: Hombre | C19: QUIM GIRON FIGUEROLA | F19: 20487801E | G19: 186282967 | H19: 31824
A20: 24 | B20: Hombre | C20: ELEAZAR DAVID FANJUL | D20: 81245927074 | E20: 1245927074 | F20: Y1339214F | G20: 186282967 | H20: 29965 | J20: 45860 | K20: FCU rc
A21: 26 | B21: Hombre | C21: PABLO MONEDERO DE ANDRES | F21: 78721589H | G21: 186282967 | H21: 27313
A22: 27 | B22: Mujer | C22: KATHARINA SOPHIA KAUDELKA | F22: Y0009880G | G22: 186282967
A23: 28 | B23: Mujer | C23: SILVIA CAPELL BOTEY | D23: 251008545865 | E23: 1008545865 | F23: 46692841N | G23: =G21 -> 186282967 | H23: 30625
A24: 29 | B24: Hombre | C24: SERGIO GONZALEZ GALLEGO | D24: 81044360973 | E24: 1044360973 | F24: 46403184V | G24: =PUNTUALES!#REF! -> #REF! | H24: 30625
A25: 30 | B25: Mujer | C25: ESTER PANÉS RODRÍGUEZ | F25: 45644169W | G25: =G24 -> #REF!
A26: 31 | B26: Mujer | C26: VICTORIA CENDAGORTA VILLALBA | D26: 80534686759 | E26: 0534686759 | F26: 37334593G | G26: =PUNTUALES!#REF! -> #REF! | H26: 26104
A27: 32 | B27: Hombre | C27: EDUARD ARNALOT MIRALLES | D27: 81029958392 | E27: 1029958392 | F27: 44980702Q | G27: =G26 -> #REF! | H27: 27680
A28: 33 | B28: Mujer | C28: MARIA AYELEN CANTINI | D28: 281338412404 | E28: 1338412404 | F28: Y0839898K | G28: =G27 -> #REF! | H28: 29673 | K28: ITA
A29: 34 | B29: Mujer | C29: MIREIA SALA MORALES | D29: 81068009270 | E29: 1068009270 | F29: 45636978X | G29: =G28 -> #REF! | H29: 29673
A30: 36 | B30: Hombre | C30: IRIA ROIBAS ESTEVE | F30: 53424899G | G30: =#REF! -> #REF! | H30: 28194 | J30: (NO HAY TARJETA SANITARIA)
A31: 37 | B31: Mujer | C31: MARIA GRAU GONZÁLEZ | D31: 81088713619 | E31: 1088713619 | F31: 47727842J | G31: =#REF! -> #REF! | H31: 30105
A32: 38 | B32: Mujer | C32: CARMEN MONTORO CUADROS | D32: 81061184817 | E32: 1061184817 | F32: 36524159K | G32: =G31 -> #REF! | H32: 28775
A33: 39 | B33: Hombre | C33: IVAN GABRIEL TOMASEVIC VUKASOVIC | D33: 81240966637 | E33: 1240966637 | F33: Y1153692A | G33: =G32 -> #REF! | H33: 28242 | J33: 13042025 | K33: RC fcu | M33: 182521791
A34: 40 | B34: Hombre | C34: NICOLAS ARANA TOMAS | D34: 281116646556 | E34: 1116646556 | F34: 48130291P | G34: =G33 -> #REF! | H34: 27431
A35: 44 | B35: Hombre | C35: ABEL FIGUERAS AGUILAR | D35: 281091475258 | E35: 1091475258 | F35: 46754067N | G35: =#REF! -> #REF! | H35: 27664
A36: 45 | B36: Mujer | C36: JOANA SERRA FORASTE | D36: 81143002903 | E36: 1143002903 | F36: 47808086X | G36: =G35 -> #REF! | H36: 30886 | I36: ES AUTONOMO
A37: 46 | B37: Hombre | C37: ROGER COMPTE ANDRES | D37: 81107269820 | E37: 1107269820 | F37: 47711869W | G37: =G36 -> #REF! | H37: 30694 | I37: CERTIFICADO EMPRESA!!!
A38: 47 | B38: Mujer | C38: MARIA MANUELA GRACIAN ALVAREZ | D38: 81140685613 | E38: 1140685613 | F38: 49551598F | G38: 182521791 | H38: 28291 | I38: REG GENERAL
A39: 48 | B39: Mujer | C39: ELENA ZANZU | F39: Y1001085R | G39: =PUNTUALES!G38 -> 182521791 | I39: (NO ENCUENTRO SU CARPETA)
A40: 49 | B40: Hombre | C40: ROBERTO ALONSO GIL | F40: 71263796K | G40: =G39 -> 182521791 | I40: (NO ENCUENTRO SU CARPETA)
...
